<?xml version="1.0"?>
<!-- created with Phobos 1.0.1 "Capricious Choutengan" -->
  <robot name="robot1">

    <link name="Body">
      <inertial>
        <origin xyz="0 0 0" rpy="0 0 0"/>
        <mass value="0.01"/>
        <inertia ixx="0.001" ixy="0" ixz="0" iyy="0.001" iyz="0" izz="0.001"/>
      </inertial>
      <visual name="Body">
        <origin xyz="0 0 0" rpy="0 0 0"/>
        <geometry>
          <mesh filename="package://robot1_pkg/meshes/stl/Body.stl" scale="0.05 0.05 0.05"/>
        </geometry>
      </visual>
      <collision name="Body.000">
        <origin xyz="0 0 0" rpy="0 0 0"/>
        <geometry>
          <mesh filename="package://robot1_pkg/meshes/stl/Body.001.stl" scale="1.0 1.0 1.0"/>
        </geometry>
      </collision>
    </link>

    <link name="Left hand 0">
      <inertial>
        <origin xyz="0 0 0" rpy="0 0 0"/>
        <mass value="0.001"/>
        <inertia ixx="0.001" ixy="0" ixz="0" iyy="0.001" iyz="0" izz="0.001"/>
      </inertial>
      <visual name="Left hand 0">
        <origin xyz="0 0 0" rpy="0 0 0"/>
        <geometry>
          <mesh filename="package://robot1_pkg/meshes/stl/Left hand 0.stl" scale="0.46 0.46 0.1"/>
        </geometry>
      </visual>
      <collision name="Left hand 0">
        <origin xyz="0 0 0" rpy="0 0 0"/>
        <geometry>
          <cylinder radius="0.46" length="0.2"/>
        </geometry>
      </collision>
    </link>

    <link name="Left hand 1">
      <inertial>
        <origin xyz="0 0 0" rpy="0 0 0"/>
        <mass value="0.001"/>
        <inertia ixx="0.001" ixy="0" ixz="0" iyy="0.001" iyz="0" izz="0.001"/>
      </inertial>
      <visual name="Left hand 1">
        <origin xyz="0 0 0" rpy="-1.5708 0 0"/>
        <geometry>
          <mesh filename="package://robot1_pkg/meshes/stl/Left hand 1.stl" scale="0.05 0.05 0.05"/>
        </geometry>
      </visual>
      <collision name="Left hand 1.000">
        <origin xyz="0 0 0" rpy="-1.5708 0 0"/>
        <geometry>
          <mesh filename="package://robot1_pkg/meshes/stl/Left hand 1.001.stl" scale="1.0 1.0 1.0"/>
        </geometry>
      </collision>
    </link>

    <link name="Left hand 2">
      <inertial>
        <origin xyz="0 0 0" rpy="0 0 0"/>
        <mass value="0.001"/>
        <inertia ixx="0.001" ixy="0" ixz="0" iyy="0.001" iyz="0" izz="0.001"/>
      </inertial>
      <visual name="Left hand 2">
        <origin xyz="0 0 0" rpy="0 0 0"/>
        <geometry>
          <mesh filename="package://robot1_pkg/meshes/stl/Left hand 2.stl" scale="0.05 0.05 0.05"/>
        </geometry>
      </visual>
      <collision name="Left hand 2.000">
        <origin xyz="0 0 0" rpy="0 0 0"/>
        <geometry>
          <mesh filename="package://robot1_pkg/meshes/stl/Left hand 2.001.stl" scale="1.0 1.0 1.0"/>
        </geometry>
      </collision>
    </link>

    <link name="Left hand 3">
      <inertial>
        <origin xyz="0 0 0" rpy="0 0 0"/>
        <mass value="0.001"/>
        <inertia ixx="0.001" ixy="0" ixz="0" iyy="0.001" iyz="0" izz="0.001"/>
      </inertial>
      <visual name="Left hand 3">
        <origin xyz="0 0 0" rpy="0 -1.5708 0"/>
        <geometry>
          <mesh filename="package://robot1_pkg/meshes/stl/Left hand 3.stl" scale="0.05 0.05 0.05"/>
        </geometry>
      </visual>
      <collision name="Left hand 3.000">
        <origin xyz="0 0 0" rpy="0 -1.5708 0"/>
        <geometry>
          <mesh filename="package://robot1_pkg/meshes/stl/Left hand 3.001.stl" scale="1.0 1.0 1.0"/>
        </geometry>
      </collision>
    </link>

    <link name="Right hand 0">
      <inertial>
        <origin xyz="0 0 0" rpy="0 0 0"/>
        <mass value="0.001"/>
        <inertia ixx="0.001" ixy="0" ixz="0" iyy="0.001" iyz="0" izz="0.001"/>
      </inertial>
      <visual name="Right hand 0">
        <origin xyz="0 0 0" rpy="0 0 0"/>
        <geometry>
          <mesh filename="package://robot1_pkg/meshes/stl/Right hand 0.stl" scale="0.46 0.46 0.1"/>
        </geometry>
      </visual>
      <collision name="Right hand 0">
        <origin xyz="0 0 0" rpy="0 0 0"/>
        <geometry>
          <cylinder radius="0.46" length="0.2"/>
        </geometry>
      </collision>
    </link>

    <link name="Right hand 1">
      <inertial>
        <origin xyz="0 0 0" rpy="0 0 0"/>
        <mass value="0.001"/>
        <inertia ixx="0.001" ixy="0" ixz="0" iyy="0.001" iyz="0" izz="0.001"/>
      </inertial>
      <visual name="Right hand 1">
        <origin xyz="0 0 0" rpy="-1.5708 0 0"/>
        <geometry>
          <mesh filename="package://robot1_pkg/meshes/stl/Right hand 1.stl" scale="0.05 0.05 0.05"/>
        </geometry>
      </visual>
      <collision name="Right hand 1.000">
        <origin xyz="0 0 0" rpy="-1.5708 0 0"/>
        <geometry>
          <mesh filename="package://robot1_pkg/meshes/stl/Right hand 1.001.stl" scale="1.0 1.0 1.0"/>
        </geometry>
      </collision>
    </link>

    <link name="Right hand 2">
      <inertial>
        <origin xyz="0 0 0" rpy="0 0 0"/>
        <mass value="0.001"/>
        <inertia ixx="0.001" ixy="0" ixz="0" iyy="0.001" iyz="0" izz="0.001"/>
      </inertial>
      <visual name="Right hand 2">
        <origin xyz="-0.04981 -0.0023 -0.15785" rpy="0 0 0"/>
        <geometry>
          <mesh filename="package://robot1_pkg/meshes/stl/Right hand 2.stl" scale="0.05 0.05 0.05"/>
        </geometry>
      </visual>
      <collision name="Right hand 2.000">
        <origin xyz="-0.04981 -0.0023 -0.15785" rpy="0 0 0"/>
        <geometry>
          <mesh filename="package://robot1_pkg/meshes/stl/Right hand 2.001.stl" scale="1.0 1.0 1.0"/>
        </geometry>
      </collision>
    </link>

    <link name="Right hand 3">
      <inertial>
        <origin xyz="0 0 0" rpy="0 0 0"/>
        <mass value="0.001"/>
        <inertia ixx="0.001" ixy="0" ixz="0" iyy="0.001" iyz="0" izz="0.001"/>
      </inertial>
      <visual name="Right hand 3">
        <origin xyz="0 0 0" rpy="0 1.5708 0"/>
        <geometry>
          <mesh filename="package://robot1_pkg/meshes/stl/Right hand 3.stl" scale="0.05 0.05 0.05"/>
        </geometry>
      </visual>
      <collision name="Right hand 3.000">
        <origin xyz="0 0 0" rpy="0 1.5708 0"/>
        <geometry>
          <mesh filename="package://robot1_pkg/meshes/stl/Right hand 3.001.stl" scale="1.0 1.0 1.0"/>
        </geometry>
      </collision>
    </link>

    <joint name="L0" type="revolute">
      <origin xyz="1.97808 1.70457 1.42065" rpy="0 1.5708 0"/>
      <parent link="Body"/>
      <child link="Left hand 0"/>
      <axis xyz="0 0 1.0"/>
      <limit lower="-1.57" upper="1.57" effort="0" velocity="0"/>
    </joint>

    <joint name="L1" type="revolute">
      <origin xyz="-0.03152 -0.50646 0.47768" rpy="1.6068 -1.5708 0"/>
      <parent link="Left hand 0"/>
      <child link="Left hand 1"/>
      <axis xyz="0 0 1.0"/>
      <limit lower="-1.4" upper="1.4" effort="0" velocity="0"/>
    </joint>

    <joint name="L2" type="revolute">
      <origin xyz="0.08791 -0.9997 -0.4857" rpy="-1.6068 0 0"/>
      <parent link="Left hand 1"/>
      <child link="Left hand 2"/>
      <axis xyz="0 0 1.0"/>
      <limit lower="-1.57" upper="1.57" effort="0" velocity="0"/>
    </joint>

    <joint name="L3" type="revolute">
      <origin xyz="0.04748 -0.04388 -0.5625" rpy="0 1.5708 0"/>
      <parent link="Left hand 2"/>
      <child link="Left hand 3"/>
      <axis xyz="0 0 1.0"/>
      <limit lower="-1.57" upper="1.57" effort="0" velocity="0"/>
    </joint>

    <joint name="R0" type="revolute">
      <origin xyz="-1.52909 1.70457 1.42065" rpy="0 1.5708 0"/>
      <parent link="Body"/>
      <child link="Right hand 0"/>
      <axis xyz="0 0 1.0"/>
      <limit lower="-1.57" upper="1.57" effort="0" velocity="0"/>
    </joint>

    <joint name="R1" type="revolute">
      <origin xyz="-0.09729 -0.51267 -0.43834" rpy="1.5708 -1.5708 0"/>
      <parent link="Right hand 0"/>
      <child link="Right hand 1"/>
      <axis xyz="0 0 1.0"/>
      <limit lower="-1.4" upper="1.4" effort="0" velocity="0"/>
    </joint>

    <joint name="R2" type="revolute">
      <origin xyz="-0.09425 -1.01818 -0.52256" rpy="-1.5708 0 0"/>
      <parent link="Right hand 1"/>
      <child link="Right hand 2"/>
      <axis xyz="0 0 1.0"/>
      <limit lower="-1.57" upper="1.57" effort="0" velocity="0"/>
    </joint>

    <joint name="R3" type="revolute">
      <origin xyz="-0.36048 -0.00781 -0.52957" rpy="0 -1.5708 0"/>
      <parent link="Right hand 2"/>
      <child link="Right hand 3"/>
      <axis xyz="0 0 1.0"/>
      <limit lower="-1.57" upper="1.57" effort="0" velocity="0"/>
    </joint>

  </robot>
